Workbook

Sheet Données MSDL
B6: UNION DES JEUNES DE DOUKA SELEYABE
G8: =+TODAY() -> 46001
B10: LISTE OFFICIELLE DES MEMBRES
M12: 2000 | T12: A JOUR | U12: GUINEE | V12: NT | W12: DETTE
B13: N° | C13: Code | D13: Téléphone | E13: Titre | F13: Désignation | G13: Missidé | H13: Pays/région | I13: Téléphone | J13: Montant mensuel MSD | K13: Montant mensuel UJDS | L13: Nbre de mois retard | M13: Amande | N13: Avance | O13: Montant dû au 15 01 25 | P13: UJDS | Q13: MOUSSIDAL | R13: STATUT | Y13: 45444 | Z13: 45474 | AA13: 45505 | AB13: 45536 | AC13: 45566 | AD13: 45597 | AE13: 45627 | AF13: 45658 | AG13: 45689 | AH13: 45717 | AI13: 45748 | AJ13: 45778 | AK13: 45809 | AL13: 45839 | AM13: 45870 | AN13: 45901 | AO13: 45931 | AP13: 45962 | AQ13: 45992
B14: 1 | C14: =CONCATENATE("N°-","000",B14,"-2024") -> N°-0001-2024 | D14: 778779867 | E14: Mr | F14: Abdoul aziz ibn Elhadji Ibrahima | G14: Pétel | H14: Dakar | I14: 77 877 98 67 | J14: 1000 | K14: N/A | L14: =+SUM($Y14:$AQ14) -> -56 | M14: =IF(L14>=0,"A JOUR",($L14*($M$12))) -> -112000 | O14: =IF(L14>=0,"A JOUR",($L14*($M$12+J14)+N14)) -> -168000 | Q14: x | T14: #N/A | U14: #N/A | V14: #N/A | W14: 1000 | X14: 56 | Y14: -52 | Z14: -1 | AA14: -1 | AB14: -1 | AC14: 0 | AD14: -1
B15: 2 | C15: =CONCATENATE("N°-","000",B15,"-2024") -> N°-0002-2024 | D15: 772175292 | E15: Koto | F15: Abdoul ghadry | G15: Leysaré | H15: Dakar | I15: 77 217 52 92 | J15: 2000 | K15: 1000 | L15: 0 | M15: =IF(L15>=0,"A JOUR",($L15*($M$12))) -> A JOUR | O15: =IF(L15>=0,"A JOUR",($L15*($M$12+J15)+N15)) -> A JOUR | P15: x | Q15: x | T15: A JOUR | Y15: 0 | Z15: 0 | AA15: 0 | AB15: 0 | AC15: 0 | AD15: 0
B16: 3 | C16: =CONCATENATE("N°-","000",B16,"-2024") -> N°-0003-2024 | D16: xxxxxxxx | E16: Mr | F16: Abdoul goudoussy | G16: Kourawoye | H16: Guinée | I16: xxxxxxxx | K16: 1000 | L16: VG | M16: =IF(L16>=0,"A JOUR",($L16*($M$12))) -> A JOUR | O16: =IF(L16>=0,"A JOUR",($L16*($M$12+J16)+N16)) -> A JOUR | P16: x | R16: VG | T16: #N/A | U16: #N/A | V16: #N/A | W16: #N/A | X16: #N/A | Y16: 0 | Z16: 0 | AA16: 0 | AB16: 0 | AC16: 0 | AD16: 0
B17: 4 | C17: =CONCATENATE("N°-","000",B17,"-2024") -> N°-0004-2024 | D17: 773528333 | E17: Kaou | F17: Abdoul malipan | G17: Dowsaré | H17: Dakar | I17: 77 352 83 33 | J17: 2000 | K17: N/A | L17: =+SUM($Y17:$AQ17) -> -25 | M17: =IF(L17>=0,"A JOUR",($L17*($M$12))) -> -50000 | O17: =IF(L17>=0,"A JOUR",($L17*($M$12+J17)+N17)) -> -100000 | Q17: x | T17: #N/A | U17: #N/A | V17: #N/A | W17: 2000 | X17: 25 | Y17: -21 | Z17: -1 | AA17: -1 | AB17: -1 | AC17: 0 | AD17: -1
B18: 5 | C18: =CONCATENATE("N°-","000",B18,"-2024") -> N°-0005-2024 | D18: xxxxxxxx | E18: Koto | F18: Abdoul salam | G18: Gobihi | H18: Gambie | I18: xxxxxxxx | J18: 2000 | K18: 1000 | M18: =IF(L18>=0,"A JOUR",($L18*($M$12))) -> A JOUR | O18: =IF(L18>=0,"A JOUR",($L18*($M$12+J18)+N18)) -> A JOUR | Q18: x | T18: #N/A | U18: #N/A | V18: #N/A | W18: #N/A | X18: #N/A | Y18: 0 | Z18: 0 | AA18: 0 | AB18: 0 | AC18: 0 | AD18: 0
B19: 6 | C19: =CONCATENATE("N°-","000",B19,"-2024") -> N°-0006-2024 | D19: 774789094 | E19: Mr | F19: Abdoul salam petit ibn bappa bala | G19: Pétel | H19: Dakar | I19: 77 478 90 94 | J19: 2000 | K19: 1000 | L19: 0 | M19: =IF(L19>=0,"A JOUR",($L19*($M$12))) -> A JOUR | O19: =IF(L19>=0,"A JOUR",($L19*($M$12+J19)+N19)) -> A JOUR | P19: x | Q19: x | T19: A JOUR | Y19: 0 | Z19: 0 | AA19: 0 | AB19: 0 | AC19: 0 | AD19: 0
B20: 7 | C20: =CONCATENATE("N°-","000",B20,"-2024") -> N°-0007-2024 | D20: 781050363 | E20: Koto | F20: Abdoul salam ibn Elhadji M. Woury VP | G20: Pétel | H20: Dakar | I20: 78 105 03 63 | J20: 2000 | K20: 1000 | L20: 0 | M20: =IF(L20>=0,"A JOUR",($L20*($M$12))) -> A JOUR | O20: =IF(L20>=0,"A JOUR",($L20*($M$12+J20)+N20)) -> A JOUR | P20: x | Q20: x | T20: A JOUR | Y20: 0 | Z20: 0 | AA20: 0 | AB20: 0 | AC20: 0 | AD20: 0
B21: 8 | C21: =CONCATENATE("N°-","000",B21,"-2024") -> N°-0008-2024 | D21: +24104506555 | E21: Mr | F21: Abdoul salam ibn karamoko Daouda | G21: Pétel | H21: Gabon | I21: +241 04 50 65 55 | J21: 5000 | K21: N/A | M21: =IF(L21>=0,"A JOUR",($L21*($M$12))) -> A JOUR | O21: =IF(L21>=0,"A JOUR",($L21*($M$12+J21)+N21)) -> A JOUR | Q21: x | T21: #N/A | U21: #N/A | V21: #N/A | W21: #N/A | X21: #N/A | Y21: 0 | Z21: 0 | AA21: 0 | AB21: 0 | AC21: 0 | AD21: 0
B22: 9 | C22: =CONCATENATE("N°-","000",B22,"-2024") -> N°-0009-2024 | D22: 774789094 | E22: Mr | F22: Abdoul salam petit | G22: Pétel | H22: Dakar | I22: 77 478 90 94 | J22: 2000 | K22: 1000 | L22: 0 | M22: =IF(L22>=0,"A JOUR",($L22*($M$12))) -> A JOUR | O22: =IF(L22>=0,"A JOUR",($L22*($M$12+J22)+N22)) -> A JOUR | P22: x | Q22: x | T22: A JOUR | Y22: 0 | Z22: 0 | AA22: 0 | AB22: 0 | AC22: 0 | AD22: 0
B23: 10 | C23: =CONCATENATE("N°-","00",B23,"-2024") -> N°-0010-2024 | D23: 776792624 | E23: Mr | F23: Abdoul salam PP | G23: Dieydiyabhe | H23: Dakar | I23: 77 679 26 24 | J23: 1000 | K23: 1000 | L23: 0 | M23: =IF(L23>=0,"A JOUR",($L23*($M$12))) -> A JOUR | O23: =IF(L23>=0,"A JOUR",($L23*($M$12+J23)+N23)) -> A JOUR | P23: x | Q23: x | T23: A JOUR | Y23: 0 | Z23: 0 | AA23: 0 | AB23: 0 | AC23: 0 | AD23: 0
B24: 11 | C24: =CONCATENATE("N°-","00",B24,"-2024") -> N°-0011-2024 | D24: 775779980 | E24: Mr | F24: Abdoul salam PP (ivoire) | G24: Dowsaré | H24: Dakar | I24: 77 577 99 80 | J24: 1000 | K24: 1000 | L24: =+SUM($Y24:$AQ24) -> -2 | M24: =IF(L24>=0,"A JOUR",($L24*($M$12))) -> -4000 | O24: =IF(L24>=0,"A JOUR",($L24*($M$12+J24)+N24)) -> -6000 | P24: x | Q24: x | T24: #N/A | U24: #N/A | V24: #N/A | W24: 1000 | X24: 2 | Y24: 0 | Z24: 0 | AA24: 0 | AB24: -1 | AC24: 0 | AD24: -1
B25: 12 | C25: =CONCATENATE("N°-","00",B25,"-2024") -> N°-0012-2024 | E25: Mr | F25: Abdoulaye | G25: Daandé Mboully | H25: Guinée | K25: 1000 | L25: VG | M25: =IF(L25>=0,"A JOUR",($L25*($M$12))) -> A JOUR | O25: =IF(L25>=0,"A JOUR",($L25*($M$12+J25)+N25)) -> A JOUR | P25: x | R25: VG | T25: #N/A | U25: #N/A | V25: #N/A | W25: #N/A | X25: #N/A | Y25: 0 | Z25: 0 | AA25: 0 | AB25: 0 | AC25: 0 | AD25: 0
B26: 13 | C26: =CONCATENATE("N°-","00",B26,"-2024") -> N°-0013-2024 | D26: xxxxxxxx | E26: Mr | F26: Abdoulaye | G26: Kourawoye | H26: Côte d'ivoire | I26: xxxxxxxx | J26: 1000 | K26: N/A | M26: =IF(L26>=0,"A JOUR",($L26*($M$12))) -> A JOUR | O26: =IF(L26>=0,"A JOUR",($L26*($M$12+J26)+N26)) -> A JOUR | P26: x | T26: #N/A | U26: #N/A | V26: #N/A | W26: #N/A | X26: #N/A | Y26: 0 | Z26: 0 | AA26: 0 | AB26: 0 | AC26: 0 | AD26: 0
B27: 14 | C27: =CONCATENATE("N°-","00",B27,"-2024") -> N°-0014-2024 | D27: 781413617 | E27: Grand | F27: Abdoulaye (Laye) | G27: Biilaa | H27: Dakar | I27: 78 141 36 17 | J27: 1000 | K27: 1000 | L27: 0 | M27: =IF(L27>=0,"A JOUR",($L27*($M$12))) -> A JOUR | O27: =IF(L27>=0,"A JOUR",($L27*($M$12+J27)+N27)) -> A JOUR | P27: x | Q27: x | T27: #N/A | U27: GUINEE | Y27: 0 | Z27: 0 | AA27: 0 | AB27: 0 | AC27: 0 | AD27: 0
B28: 15 | C28: =CONCATENATE("N°-","00",B28,"-2024") -> N°-0015-2024 | D28: +24106399421 | E28: Grand | F28: Abdoulaye (Laye) gabonais | G28: Pétel | H28: Dakar | I28: +241 06 39 94 21 | J28: 2000 | K28: N/A | L28: =+SUM($Y28:$AQ28) -> -4 | M28: =IF(L28>=0,"A JOUR",($L28*($M$12))) -> -8000 | O28: =IF(L28>=0,"A JOUR",($L28*($M$12+J28)+N28)) -> -16000 | Q28: x | T28: #N/A | U28: #N/A | V28: #N/A | W28: 2000 | X28: 4 | Y28: 0 | Z28: -1 | AA28: -1 | AB28: -1 | AC28: 0 | AD28: -1
B29: 16 | C29: =CONCATENATE("N°-","00",B29,"-2024") -> N°-0016-2024 | D29: 777255426 | E29: Mr | F29: Abdoulaye djibril KZA ibnou samara | G29: Dowsaré | H29: Casamance | I29: 77 725 54 26 | J29: 1500 | K29: N/A | L29: 0 | M29: =IF(L29>=0,"A JOUR",($L29*($M$12))) -> A JOUR | O29: =IF(L29>=0,"A JOUR",($L29*($M$12+J29)+N29)) -> A JOUR | P29: x | Q29: x | T29: A JOUR | Y29: 0 | Z29: 0 | AA29: 0 | AB29: 0 | AC29: 0 | AD29: 0
B30: 17 | C30: =CONCATENATE("N°-","00",B30,"-2024") -> N°-0017-2024 | E30: Mr | F30: Abdoulaye ka gallé | G30: Biilaa | H30: Guinée | K30: N/A | L30: VG | M30: =IF(L30>=0,"A JOUR",($L30*($M$12))) -> A JOUR | O30: =IF(L30>=0,"A JOUR",($L30*($M$12+J30)+N30)) -> A JOUR | R30: VG | T30: #N/A | U30: #N/A | V30: #N/A | W30: #N/A | X30: #N/A | Y30: 0 | Z30: 0 | AA30: 0 | AB30: 0 | AC30: 0 | AD30: 0
B31: 18 | C31: =CONCATENATE("N°-","00",B31,"-2024") -> N°-0018-2024 | D31: 774042497 | E31: Mr | F31: Abdourahmane TRS | G31: Mamasamba | H31: Dakar | I31: 77 404 24 97 | J31: 5000 | K31: 1000 | L31: 0 | M31: =IF(L31>=0,"A JOUR",($L31*($M$12))) -> A JOUR | O31: =IF(L31>=0,"A JOUR",($L31*($M$12+J31)+N31)) -> A JOUR | P31: x | Q31: x | T31: #N/A | U31: #N/A | V31: #N/A | W31: #N/A | X31: #N/A | Y31: 0 | Z31: 0 | AA31: 0 | AB31: 0 | AC31: 0 | AD31: 0
B32: 19 | C32: =CONCATENATE("N°-","00",B32,"-2024") -> N°-0019-2024 | D32: 774473167 | E32: Koto | F32: Ablaye TSA | G32: Bolorrou | H32: Dakar | I32: 77 447 31 67 | J32: 1500 | K32: 1000 | L32: 0 | M32: =IF(L32>=0,"A JOUR",($L32*($M$12))) -> A JOUR | O32: =IF(L32>=0,"A JOUR",($L32*($M$12+J32)+N32)) -> A JOUR | P32: x | Q32: x | T32: A JOUR | Y32: 0 | Z32: 0 | AA32: 0 | AB32: 0 | AC32: 0 | AD32: 0
B33: 20 | C33: =CONCATENATE("N°-","00",B33,"-2024") -> N°-0020-2024 | D33: 777119328 | E33: Kaou | F33: Ahmadou Korka ibn bappa bala | G33: Pétel | H33: Dakar | I33: 777119328 | J33: 1000 | K33: 1000 | L33: =+SUM($Y33:$AQ33) -> -3 | M33: =IF(L33>=0,"A JOUR",($L33*($M$12))) -> -6000 | O33: =IF(L33>=0,"A JOUR",($L33*($M$12+J33)+N33)) -> -9000 | T33: #N/A | U33: #N/A | V33: #N/A | W33: 1000 | X33: 3 | Y33: 0 | Z33: 0 | AA33: -1 | AB33: -1 | AC33: 0 | AD33: -1
B34: 21 | C34: =CONCATENATE("N°-","00",B34,"-2024") -> N°-0021-2024 | D34: 783520425 | E34: Mr | F34: Alassana ibn Elhadji M. Woury | G34: Pétel | H34: Dakar | I34: 78 352 04 25 | J34: 1000 | K34: 1000 | L34: 0 | M34: =IF(L34>=0,"A JOUR",($L34*($M$12))) -> A JOUR | O34: =IF(L34>=0,"A JOUR",($L34*($M$12+J34)+N34)) -> A JOUR | Q34: x | R34: NT | T34: #N/A | U34: #N/A | V34: NT | Y34: 0 | Z34: 0 | AA34: 0 | AB34: 0 | AC34: 0 | AD34: 0
B35: 22 | C35: =CONCATENATE("N°-","00",B35,"-2024") -> N°-0022-2024 | D35: 767652193 | E35: Mr | F35: Alassana Macoss | G35: Dowsaré | H35: Dakar | I35: 76 765 21 93 | J35: 1000 | K35: 1000 | L35: 0 | M35: =IF(L35>=0,"A JOUR",($L35*($M$12))) -> A JOUR | O35: =IF(L35>=0,"A JOUR",($L35*($M$12+J35)+N35)) -> A JOUR | P35: x | Q35: x | R35: NT | T35: #N/A | U35: #N/A | V35: NT | Y35: 0 | Z35: 0 | AA35: 0 | AB35: 0 | AC35: 0 | AD35: 0
B36: 23 | C36: =CONCATENATE("N°-","00",B36,"-2024") -> N°-0023-2024 | D36: 783520425 | E36: Mr | F36: Alousseynou ibn Elhadji M. Woury | G36: Pétel | H36: Dakar | I36: 78 352 04 25 | J36: 1000 | K36: 1000 | L36: 0 | M36: =IF(L36>=0,"A JOUR",($L36*($M$12))) -> A JOUR | O36: =IF(L36>=0,"A JOUR",($L36*($M$12+J36)+N36)) -> A JOUR | Q36: x | R36: NT | T36: #N/A | U36: #N/A | V36: NT | Y36: 0 | Z36: 0 | AA36: 0 | AB36: 0 | AC36: 0 | AD36: 0
B37: 24 | C37: =CONCATENATE("N°-","00",B37,"-2024") -> N°-0024-2024 | E37: Mr | F37: Alousseynou Pecosse | G37: Dowsaré | H37: Guinée | K37: N/A | L37: VG | M37: =IF(L37>=0,"A JOUR",($L37*($M$12))) -> A JOUR | O37: =IF(L37>=0,"A JOUR",($L37*($M$12+J37)+N37)) -> A JOUR | P37: x | R37: VG | T37: #N/A | U37: #N/A | V37: #N/A | W37: #N/A | X37: #N/A | Y37: 0 | Z37: 0 | AA37: 0 | AB37: 0 | AC37: 0 | AD37: 0
B38: 25 | C38: =CONCATENATE("N°-","00",B38,"-2024") -> N°-0025-2024 | E38: Mr | F38: Alpha (France) | G38: Dieydiyabhe | H38: France | K38: 1000 | M38: =IF(L38>=0,"A JOUR",($L38*($M$12))) -> A JOUR | O38: =IF(L38>=0,"A JOUR",($L38*($M$12+J38)+N38)) -> A JOUR | T38: #N/A | U38: #N/A | V38: #N/A | W38: #N/A | X38: #N/A | Y38: 0 | Z38: 0 | AA38: 0 | AB38: 0 | AC38: 0 | AD38: 0
B39: 26 | C39: =CONCATENATE("N°-","00",B39,"-2024") -> N°-0026-2024 | D39: 772289487 | E39: Mr | F39: Alpha amadou ibn bappa bala | G39: Pétel | H39: Dakar | I39: 77 228 94 87 | J39: 1000 | K39: 1000 | L39: 0 | M39: =IF(L39>=0,"A JOUR",($L39*($M$12))) -> A JOUR | O39: =IF(L39>=0,"A JOUR",($L39*($M$12+J39)+N39)) -> A JOUR | P39: x | Q39: x | T39: A JOUR | Y39: 0 | Z39: 0 | AA39: 0 | AB39: 0 | AC39: 0 | AD39: 0
B40: 27 | C40: =CONCATENATE("N°-","00",B40,"-2024") -> N°-0027-2024 | D40: 781261182 | E40: Mr | F40: Alpha Amirou ibn Elhadji Ibrahima | G40: Pétel | H40: Dakar | I40: 78 126 11 82 | J40: 1000 | K40: 1000 | L40: =+SUM($Y40:$AQ40) -> -6 | M40: =IF(L40>=0,"A JOUR",($L40*($M$12))) -> -12000 | O40: =IF(L40>=0,"A JOUR",($L40*($M$12+J40)+N40)) -> -18000 | Q40: x | R40: NT | T40: #N/A | U40: #N/A | V40: #N/A | W40: 1000 | X40: 6 | Y40: -2 | Z40: -1 | AA40: -1 | AB40: -1 | AC40: 0 | AD40: -1
B41: 28 | C41: =CONCATENATE("N°-","00",B41,"-2024") -> N°-0028-2024 | D41: 772202046 | E41: Koto | F41: alpha KZA ibnou samara | G41: Dowsaré | H41: Casamance | I41: 77 220 20 46 | J41: 2000 | K41: 1000 | L41: 1 | M41: =IF(L41>=0,"A JOUR",($L41*($M$12))) -> A JOUR | N41: =+L41*J41 -> 2000 | O41: =IF(L41>=0,"A JOUR",($L41*($M$12+J41)+N41)) -> A JOUR | P41: x | Q41: x | T41: A JOUR | Y41: 0 | Z41: 0 | AA41: 0 | AB41: 0 | AC41: 0 | AD41: 0
B42: 29 | C42: =CONCATENATE("N°-","00",B42,"-2024") -> N°-0029-2024 | D42: 781346347 | E42: Bappa | F42: Alpha oumar | G42: Mamasamba | H42: Dakar | I42: 78 134 63 47 | J42: 2000 | K42: 1000 | L42: =4-4 -> 0 | M42: =IF(L42>=0,"A JOUR",($L42*($M$12))) -> A JOUR | O42: =IF(L42>=0,"A JOUR",($L42*($M$12+J42)+N42)) -> A JOUR | P42: x | Q42: x | T42: A JOUR | Y42: 0 | Z42: 0 | AA42: 0 | AB42: 0 | AC42: 0 | AD42: 0
B43: 30 | C43: =CONCATENATE("N°-","00",B43,"-2024") -> N°-0030-2024 | D43: xxxxxxxx | E43: Koto | F43: Alpha oumar gabonais | G43: Dowsaré | H43: Togo | I43: xxxxxxxx | J43: 4000 | K43: 1000 | M43: =IF(L43>=0,"A JOUR",($L43*($M$12))) -> A JOUR | O43: =IF(L43>=0,"A JOUR",($L43*($M$12+J43)+N43)) -> A JOUR | P43: x | Q43: x | T43: #N/A | U43: #N/A | V43: #N/A | W43: #N/A | X43: #N/A | Y43: 0 | Z43: 0 | AA43: 0 | AB43: 0 | AC43: 0 | AD43: 0
B44: 31 | C44: =CONCATENATE("N°-","00",B44,"-2024") -> N°-0031-2024 | D44: +24102253222 | E44: Koto | F44: Alpha oumar ibn karamoko Daouda | G44: Pétel | H44: Gabon | I44: +241 02 25 32 22 | J44: 5000 | K44: N/A | M44: =IF(L44>=0,"A JOUR",($L44*($M$12))) -> A JOUR | O44: =IF(L44>=0,"A JOUR",($L44*($M$12+J44)+N44)) -> A JOUR | Q44: x | T44: #N/A | U44: #N/A | V44: #N/A | W44: #N/A | X44: #N/A | Y44: 0 | Z44: 0 | AA44: 0 | AB44: 0 | AC44: 0 | AD44: 0
B45: 32 | C45: =CONCATENATE("N°-","00",B45,"-2024") -> N°-0032-2024 | D45: 774997775 | E45: Koto | F45: Alpha Oumar togolais | G45: Dowsaré | H45: Dakar | I45: 77 499 77 75 | J45: 2000 | K45: 1000 | L45: =2-1 -> 1 | M45: =IF(L45>=0,"A JOUR",($L45*($M$12))) -> A JOUR | N45: =+L45*J45 -> 2000 | O45: =IF(L45>=0,"A JOUR",($L45*($M$12+J45)+N45)) -> A JOUR | P45: x | Q45: x | T45: A JOUR | Y45: 0 | Z45: 0 | AA45: 0 | AB45: 0 | AC45: 0 | AD45: 0
B46: 33 | C46: =CONCATENATE("N°-","00",B46,"-2024") -> N°-0033-2024 | E46: Mr | F46: Alpha Saliou ibn Elhadji M. Woury | G46: Pétel | H46: Guinée | K46: 1000 | L46: VG | M46: =IF(L46>=0,"A JOUR",($L46*($M$12))) -> A JOUR | O46: =IF(L46>=0,"A JOUR",($L46*($M$12+J46)+N46)) -> A JOUR | R46: VG | T46: #N/A | U46: #N/A | V46: #N/A | W46: #N/A | X46: #N/A | Y46: 0 | Z46: 0 | AA46: 0 | AB46: 0 | AC46: 0 | AD46: 0
B47: 34 | C47: =CONCATENATE("N°-","00",B47,"-2024") -> N°-0034-2024 | D47: 776709584 | E47: Oustaz | F47: Amadou | G47: Bowell | H47: Guinée | I47: 77 670 95 84 | J47: 2500 | K47: 1000 | L47: 0 | M47: =IF(L47>=0,"A JOUR",($L47*($M$12))) -> A JOUR | O47: =IF(L47>=0,"A JOUR",($L47*($M$12+J47)+N47)) -> A JOUR | P47: x | Q47: x | R47: NT | T47: #N/A | U47: GUINEE | Y47: 0 | Z47: 0 | AA47: 0 | AB47: 0 | AC47: 0 | AD47: 0
B48: 35 | C48: =CONCATENATE("N°-","00",B48,"-2024") -> N°-0035-2024 | D48: 776623868 | E48: Mr | F48: Amadou bobo (mariste) | G48: Dowsaré | H48: Dakar | I48: 77 662 38 68 | J48: 2000 | K48: 1000 | L48: 0 | M48: =IF(L48>=0,"A JOUR",($L48*($M$12))) -> A JOUR | O48: =IF(L48>=0,"A JOUR",($L48*($M$12+J48)+N48)) -> A JOUR | P48: x | Q48: x | T48: A JOUR | Y48: 0 | Z48: 0 | AA48: 0 | AB48: 0 | AC48: 0 | AD48: 0
...

Sheet Données UJDS
B6: UNION DES JEUNES DE DOUKA SELEYABE
G8: =+TODAY() -> 46001
B10: LISTE OFFICIELLE DES MEMBRES
M12: 2000 | T12: A JOUR | U12: GUINEE | V12: NT | W12: DETTE
B13: N° | C13: Code | D13: Téléphone | E13: Titre | F13: Désignation | G13: Missidé | H13: Pays/région | I13: Téléphone | J13: Montant mensuel MSD | K13: Montant mensuel UJDS | L13: Nbre de mois retard | M13: Amande | N13: Avance | O13: Montant dû au 15 01 25 | P13: UJDS | Q13: MOUSSIDAL | R13: STATUT | Y13: 45444 | Z13: 45474 | AA13: 45505 | AB13: 45536 | AC13: 45566 | AD13: 45597 | AE13: 45627 | AF13: 45658 | AG13: 45689 | AH13: 45717 | AI13: 45748 | AJ13: 45778 | AK13: 45809 | AL13: 45839 | AM13: 45870 | AN13: 45901 | AO13: 45931 | AP13: 45962 | AQ13: 45992
B14: 2 | C14: =CONCATENATE("N°-","000",B14,"-2024") -> N°-0002-2024 | D14: 772175292 | E14: Koto | F14: Abdoul ghadry | G14: Leysaré | H14: Dakar | I14: 77 217 52 92 | J14: 2000 | K14: 1000 | L14: 0 | M14: =IF(L14>=0,"A JOUR",($L14*($M$12))) -> A JOUR | O14: =IF(L14>=0,"A JOUR",($L14*($M$12+J14))) -> A JOUR | P14: x | Q14: x | T14: A JOUR | Y14: 0 | Z14: 0 | AA14: 0 | AB14: 0 | AC14: 0 | AD14: 0
B15: 3 | C15: =CONCATENATE("N°-","000",B15,"-2024") -> N°-0003-2024 | D15: xxxxxxxx | E15: Mr | F15: Abdoul goudoussy | G15: Kourawoye | H15: Guinée | I15: xxxxxxxx | K15: 1000 | L15: VG | M15: =IF(L15>=0,"A JOUR",($L15*($M$12))) -> A JOUR | O15: =IF(L15>=0,"A JOUR",($L15*($M$12+J15))) -> A JOUR | P15: x | R15: VG | T15: #N/A | U15: #N/A | V15: #N/A | W15: #N/A | X15: #N/A | Y15: 0 | Z15: 0 | AA15: 0 | AB15: 0 | AC15: 0 | AD15: 0
B16: 5 | C16: =CONCATENATE("N°-","000",B16,"-2024") -> N°-0005-2024 | D16: xxxxxxxx | E16: Koto | F16: Abdoul salam | G16: Gobihi | H16: Gambie | I16: xxxxxxxx | J16: 2000 | K16: 1000 | M16: =IF(L16>=0,"A JOUR",($L16*($M$12))) -> A JOUR | O16: =IF(L16>=0,"A JOUR",($L16*($M$12+J16))) -> A JOUR | Q16: x | T16: #N/A | U16: #N/A | V16: #N/A | W16: #N/A | X16: #N/A | Y16: 0 | Z16: 0 | AA16: 0 | AB16: 0 | AC16: 0 | AD16: 0
B17: 6 | C17: =CONCATENATE("N°-","000",B17,"-2024") -> N°-0006-2024 | D17: 774789094 | E17: Mr | F17: Abdoul salam petit ibn bappa bala | G17: Pétel | H17: Dakar | I17: 77 478 90 94 | J17: 2000 | K17: 1000 | L17: 0 | M17: =IF(L17>=0,"A JOUR",($L17*($M$12))) -> A JOUR | O17: =IF(L17>=0,"A JOUR",($L17*($M$12+J17))) -> A JOUR | P17: x | Q17: x | T17: A JOUR | Y17: 0 | Z17: 0 | AA17: 0 | AB17: 0 | AC17: 0 | AD17: 0
B18: 7 | C18: =CONCATENATE("N°-","000",B18,"-2024") -> N°-0007-2024 | D18: 781050363 | E18: Koto | F18: Abdoul salam ibn Elhadji M. Woury VP | G18: Pétel | H18: Dakar | I18: 78 105 03 63 | J18: 2000 | K18: 1000 | L18: 0 | M18: =IF(L18>=0,"A JOUR",($L18*($M$12))) -> A JOUR | O18: =IF(L18>=0,"A JOUR",($L18*($M$12+J18))) -> A JOUR | P18: x | Q18: x | T18: A JOUR | Y18: 0 | Z18: 0 | AA18: 0 | AB18: 0 | AC18: 0 | AD18: 0
B19: 9 | C19: =CONCATENATE("N°-","000",B19,"-2024") -> N°-0009-2024 | D19: 774789094 | E19: Mr | F19: Abdoul salam petit | G19: Pétel | H19: Dakar | I19: 77 478 90 94 | J19: 2000 | K19: 1000 | L19: 0 | M19: =IF(L19>=0,"A JOUR",($L19*($M$12))) -> A JOUR | O19: =IF(L19>=0,"A JOUR",($L19*($M$12+J19))) -> A JOUR | P19: x | Q19: x | T19: A JOUR | Y19: 0 | Z19: 0 | AA19: 0 | AB19: 0 | AC19: 0 | AD19: 0
B20: 10 | C20: =CONCATENATE("N°-","00",B20,"-2024") -> N°-0010-2024 | D20: 776792624 | E20: Mr | F20: Abdoul salam PP | G20: Dieydiyabhe | H20: Dakar | I20: 77 679 26 24 | J20: 1000 | K20: 1000 | L20: 0 | M20: =IF(L20>=0,"A JOUR",($L20*($M$12))) -> A JOUR | O20: =IF(L20>=0,"A JOUR",($L20*($M$12+J20))) -> A JOUR | P20: x | Q20: x | T20: A JOUR | Y20: 0 | Z20: 0 | AA20: 0 | AB20: 0 | AC20: 0 | AD20: 0
B21: 11 | C21: =CONCATENATE("N°-","00",B21,"-2024") -> N°-0011-2024 | D21: 775779980 | E21: Mr | F21: Abdoul salam PP (ivoire) | G21: Dowsaré | H21: Dakar | I21: 77 577 99 80 | J21: 1000 | K21: 1000 | L21: =+SUM($Y21:$AQ21) -> -2 | M21: =IF(L21>=0,"A JOUR",($L21*($M$12))) -> -4000 | O21: =IF(L21>=0,"A JOUR",($L21*($M$12+J21)+N21)) -> -6000 | P21: x | Q21: x | T21: #N/A | U21: #N/A | V21: #N/A | W21: 1000 | X21: 2 | Y21: 0 | Z21: 0 | AA21: 0 | AB21: -1 | AC21: 0 | AD21: -1
B22: 12 | C22: =CONCATENATE("N°-","00",B22,"-2024") -> N°-0012-2024 | E22: Mr | F22: Abdoulaye | G22: Daandé Mboully | H22: Guinée | K22: 1000 | L22: VG | M22: =IF(L22>=0,"A JOUR",($L22*($M$12))) -> A JOUR | O22: =IF(L22>=0,"A JOUR",($L22*($M$12+J22))) -> A JOUR | P22: x | R22: VG | T22: #N/A | U22: #N/A | V22: #N/A | W22: #N/A | X22: #N/A | Y22: 0 | Z22: 0 | AA22: 0 | AB22: 0 | AC22: 0 | AD22: 0
B23: 14 | C23: =CONCATENATE("N°-","00",B23,"-2024") -> N°-0014-2024 | D23: 781413617 | E23: Grand | F23: Abdoulaye (Laye) | G23: Biilaa | H23: Dakar | I23: 78 141 36 17 | J23: 1000 | K23: 1000 | L23: 0 | M23: =IF(L23>=0,"A JOUR",($L23*($M$12))) -> A JOUR | O23: =IF(L23>=0,"A JOUR",($L23*($M$12+J23))) -> A JOUR | P23: x | Q23: x | T23: #N/A | U23: GUINEE | Y23: 0 | Z23: 0 | AA23: 0 | AB23: 0 | AC23: 0 | AD23: 0
B24: 18 | C24: =CONCATENATE("N°-","00",B24,"-2024") -> N°-0018-2024 | D24: 774042497 | E24: Mr | F24: Abdourahmane TRS | G24: Mamasamba | H24: Dakar | I24: 77 404 24 97 | J24: 5000 | K24: 1000 | L24: 0 | M24: =IF(L24>=0,"A JOUR",($L24*($M$12))) -> A JOUR | O24: =IF(L24>=0,"A JOUR",($L24*($M$12+J24))) -> A JOUR | P24: x | Q24: x | T24: #N/A | U24: #N/A | V24: #N/A | W24: #N/A | X24: #N/A | Y24: 0 | Z24: 0 | AA24: 0 | AB24: 0 | AC24: 0 | AD24: 0
B25: 19 | C25: =CONCATENATE("N°-","00",B25,"-2024") -> N°-0019-2024 | D25: 774473167 | E25: Koto | F25: Ablaye TSA | G25: Bolorrou | H25: Dakar | I25: 77 447 31 67 | J25: 1500 | K25: 1000 | L25: 0 | M25: =IF(L25>=0,"A JOUR",($L25*($M$12))) -> A JOUR | O25: =IF(L25>=0,"A JOUR",($L25*($M$12+J25))) -> A JOUR | P25: x | Q25: x | T25: A JOUR | Y25: 0 | Z25: 0 | AA25: 0 | AB25: 0 | AC25: 0 | AD25: 0
B26: 20 | C26: =CONCATENATE("N°-","00",B26,"-2024") -> N°-0020-2024 | D26: 777119328 | E26: Kaou | F26: Ahmadou Korka ibn bappa bala | G26: Pétel | H26: Dakar | I26: 777119328 | J26: 1000 | K26: 1000 | L26: =+SUM($Y26:$AQ26) -> -3 | M26: =IF(L26>=0,"A JOUR",($L26*($M$12))) -> -6000 | O26: =IF(L26>=0,"A JOUR",($L26*($M$12+J26)+N26)) -> -9000 | T26: #N/A | U26: #N/A | V26: #N/A | W26: 1000 | X26: 3 | Y26: 0 | Z26: 0 | AA26: -1 | AB26: -1 | AC26: 0 | AD26: -1
B27: 21 | C27: =CONCATENATE("N°-","00",B27,"-2024") -> N°-0021-2024 | D27: 783520425 | E27: Mr | F27: Alassana ibn Elhadji M. Woury | G27: Pétel | H27: Dakar | I27: 78 352 04 25 | J27: 1000 | K27: 1000 | L27: 0 | M27: =IF(L27>=0,"A JOUR",($L27*($M$12))) -> A JOUR | O27: =IF(L27>=0,"A JOUR",($L27*($M$12+J27))) -> A JOUR | Q27: x | R27: NT | T27: #N/A | U27: #N/A | V27: NT | Y27: 0 | Z27: 0 | AA27: 0 | AB27: 0 | AC27: 0 | AD27: 0
B28: 22 | C28: =CONCATENATE("N°-","00",B28,"-2024") -> N°-0022-2024 | D28: 767652193 | E28: Mr | F28: Alassana Macoss | G28: Dowsaré | H28: Dakar | I28: 76 765 21 93 | J28: 1000 | K28: 1000 | L28: 0 | M28: =IF(L28>=0,"A JOUR",($L28*($M$12))) -> A JOUR | O28: =IF(L28>=0,"A JOUR",($L28*($M$12+J28))) -> A JOUR | P28: x | Q28: x | R28: NT | T28: #N/A | U28: #N/A | V28: NT | Y28: 0 | Z28: 0 | AA28: 0 | AB28: 0 | AC28: 0 | AD28: 0
B29: 23 | C29: =CONCATENATE("N°-","00",B29,"-2024") -> N°-0023-2024 | D29: 783520425 | E29: Mr | F29: Alousseynou ibn Elhadji M. Woury | G29: Pétel | H29: Dakar | I29: 78 352 04 25 | J29: 1000 | K29: 1000 | L29: 0 | M29: =IF(L29>=0,"A JOUR",($L29*($M$12))) -> A JOUR | O29: =IF(L29>=0,"A JOUR",($L29*($M$12+J29))) -> A JOUR | Q29: x | R29: NT | T29: #N/A | U29: #N/A | V29: NT | Y29: 0 | Z29: 0 | AA29: 0 | AB29: 0 | AC29: 0 | AD29: 0
B30: 25 | C30: =CONCATENATE("N°-","00",B30,"-2024") -> N°-0025-2024 | E30: Mr | F30: Alpha (France) | G30: Dieydiyabhe | H30: France | K30: 1000 | M30: =IF(L30>=0,"A JOUR",($L30*($M$12))) -> A JOUR | O30: =IF(L30>=0,"A JOUR",($L30*($M$12+J30))) -> A JOUR | T30: #N/A | U30: #N/A | V30: #N/A | W30: #N/A | X30: #N/A | Y30: 0 | Z30: 0 | AA30: 0 | AB30: 0 | AC30: 0 | AD30: 0
B31: 26 | C31: =CONCATENATE("N°-","00",B31,"-2024") -> N°-0026-2024 | D31: 772289487 | E31: Mr | F31: Alpha amadou ibn bappa bala | G31: Pétel | H31: Dakar | I31: 77 228 94 87 | J31: 1000 | K31: 1000 | L31: 0 | M31: =IF(L31>=0,"A JOUR",($L31*($M$12))) -> A JOUR | O31: =IF(L31>=0,"A JOUR",($L31*($M$12+J31))) -> A JOUR | P31: x | Q31: x | T31: A JOUR | Y31: 0 | Z31: 0 | AA31: 0 | AB31: 0 | AC31: 0 | AD31: 0
B32: 27 | C32: =CONCATENATE("N°-","00",B32,"-2024") -> N°-0027-2024 | D32: 781261182 | E32: Mr | F32: Alpha Amirou ibn Elhadji Ibrahima | G32: Pétel | H32: Dakar | I32: 78 126 11 82 | J32: 1000 | K32: 1000 | L32: =+SUM($Y32:$AQ32) -> -6 | M32: =IF(L32>=0,"A JOUR",($L32*($M$12))) -> -12000 | O32: =IF(L32>=0,"A JOUR",($L32*($M$12+J32)+N32)) -> -18000 | Q32: x | R32: NT | T32: #N/A | U32: #N/A | V32: #N/A | W32: 1000 | X32: 6 | Y32: -2 | Z32: -1 | AA32: -1 | AB32: -1 | AC32: 0 | AD32: -1
B33: 28 | C33: =CONCATENATE("N°-","00",B33,"-2024") -> N°-0028-2024 | D33: 772202046 | E33: Koto | F33: alpha KZA ibnou samara | G33: Dowsaré | H33: Casamance | I33: 77 220 20 46 | J33: 2000 | K33: 1000 | L33: 1 | M33: =IF(L33>=0,"A JOUR",($L33*($M$12))) -> A JOUR | N33: =+L33*J33 -> 2000 | O33: =IF(L33>=0,"A JOUR",($L33*($M$12+J33))) -> A JOUR | P33: x | Q33: x | T33: A JOUR | Y33: 0 | Z33: 0 | AA33: 0 | AB33: 0 | AC33: 0 | AD33: 0
B34: 29 | C34: =CONCATENATE("N°-","00",B34,"-2024") -> N°-0029-2024 | D34: 781346347 | E34: Bappa | F34: Alpha oumar | G34: Mamasamba | H34: Dakar | I34: 78 134 63 47 | J34: 2000 | K34: 1000 | L34: =4-4 -> 0 | M34: =IF(L34>=0,"A JOUR",($L34*($M$12))) -> A JOUR | O34: =IF(L34>=0,"A JOUR",($L34*($M$12+J34))) -> A JOUR | P34: x | Q34: x | T34: A JOUR | Y34: 0 | Z34: 0 | AA34: 0 | AB34: 0 | AC34: 0 | AD34: 0
B35: 30 | C35: =CONCATENATE("N°-","00",B35,"-2024") -> N°-0030-2024 | D35: xxxxxxxx | E35: Koto | F35: Alpha oumar gabonais | G35: Dowsaré | H35: Togo | I35: xxxxxxxx | J35: 4000 | K35: 1000 | M35: =IF(L35>=0,"A JOUR",($L35*($M$12))) -> A JOUR | O35: =IF(L35>=0,"A JOUR",($L35*($M$12+J35))) -> A JOUR | P35: x | Q35: x | T35: #N/A | U35: #N/A | V35: #N/A | W35: #N/A | X35: #N/A | Y35: 0 | Z35: 0 | AA35: 0 | AB35: 0 | AC35: 0 | AD35: 0
B36: 32 | C36: =CONCATENATE("N°-","00",B36,"-2024") -> N°-0032-2024 | D36: 774997775 | E36: Koto | F36: Alpha Oumar togolais | G36: Dowsaré | H36: Dakar | I36: 77 499 77 75 | J36: 2000 | K36: 1000 | L36: =2-1 -> 1 | M36: =IF(L36>=0,"A JOUR",($L36*($M$12))) -> A JOUR | N36: =+L36*J36 -> 2000 | O36: =IF(L36>=0,"A JOUR",($L36*($M$12+J36))) -> A JOUR | P36: x | Q36: x | T36: A JOUR | Y36: 0 | Z36: 0 | AA36: 0 | AB36: 0 | AC36: 0 | AD36: 0
B37: 33 | C37: =CONCATENATE("N°-","00",B37,"-2024") -> N°-0033-2024 | E37: Mr | F37: Alpha Saliou ibn Elhadji M. Woury | G37: Pétel | H37: Guinée | K37: 1000 | L37: VG | M37: =IF(L37>=0,"A JOUR",($L37*($M$12))) -> A JOUR | O37: =IF(L37>=0,"A JOUR",($L37*($M$12+J37))) -> A JOUR | R37: VG | T37: #N/A | U37: #N/A | V37: #N/A | W37: #N/A | X37: #N/A | Y37: 0 | Z37: 0 | AA37: 0 | AB37: 0 | AC37: 0 | AD37: 0
B38: 34 | C38: =CONCATENATE("N°-","00",B38,"-2024") -> N°-0034-2024 | D38: 776709584 | E38: Oustaz | F38: Amadou | G38: Bowell | H38: Guinée | I38: 77 670 95 84 | J38: 2500 | K38: 1000 | L38: 0 | M38: =IF(L38>=0,"A JOUR",($L38*($M$12))) -> A JOUR | O38: =IF(L38>=0,"A JOUR",($L38*($M$12+J38))) -> A JOUR | P38: x | Q38: x | R38: NT | T38: #N/A | U38: GUINEE | Y38: 0 | Z38: 0 | AA38: 0 | AB38: 0 | AC38: 0 | AD38: 0
B39: 35 | C39: =CONCATENATE("N°-","00",B39,"-2024") -> N°-0035-2024 | D39: 776623868 | E39: Mr | F39: Amadou bobo (mariste) | G39: Dowsaré | H39: Dakar | I39: 77 662 38 68 | J39: 2000 | K39: 1000 | L39: 0 | M39: =IF(L39>=0,"A JOUR",($L39*($M$12))) -> A JOUR | O39: =IF(L39>=0,"A JOUR",($L39*($M$12+J39))) -> A JOUR | P39: x | Q39: x | T39: A JOUR | Y39: 0 | Z39: 0 | AA39: 0 | AB39: 0 | AC39: 0 | AD39: 0
B40: 36 | C40: =CONCATENATE("N°-","00",B40,"-2024") -> N°-0036-2024 | D40: 774272026 | E40: Koto | F40: Amadou bobo N°1 | G40: Dowsaré | H40: Dakar | I40: 77 427 20 26 | J40: 2000 | K40: 1000 | L40: =+SUM($Y40:$AQ40) -> -4 | M40: =IF(L40>=0,"A JOUR",($L40*($M$12))) -> -8000 | O40: =IF(L40>=0,"A JOUR",($L40*($M$12+J40)+N40)) -> -16000 | P40: x | Q40: x | T40: #N/A | U40: #N/A | V40: #N/A | W40: 2000 | X40: 4 | Y40: 0 | Z40: -1 | AA40: -1 | AB40: -1 | AC40: 0 | AD40: -1
B41: 37 | C41: =CONCATENATE("N°-","00",B41,"-2024") -> N°-0037-2024 | D41: xxxxxxxx | E41: Mr | F41: Amadou diogo | G41: Gobihi | H41: Guinée | I41: xxxxxxxx | J41: 2000 | K41: 1000 | M41: =IF(L41>=0,"A JOUR",($L41*($M$12))) -> A JOUR | O41: =IF(L41>=0,"A JOUR",($L41*($M$12+J41))) -> A JOUR | Q41: x | R41: VG | T41: #N/A | U41: #N/A | V41: #N/A | W41: #N/A | X41: #N/A | Y41: 0 | Z41: 0 | AA41: 0 | AB41: 0 | AC41: 0 | AD41: 0
B42: 38 | C42: =CONCATENATE("N°-","00",B42,"-2024") -> N°-0038-2024 | D42: 775218573 | E42: Mr | F42: Amadou Djoulde - PR | G42: Dowsaré | H42: Dakar | I42: 77 521 85 73 | J42: 3000 | K42: 1000 | L42: 0 | M42: =IF(L42>=0,"A JOUR",($L42*($M$12))) -> A JOUR | O42: =IF(L42>=0,"A JOUR",($L42*($M$12+J42))) -> A JOUR | P42: x | Q42: x | T42: A JOUR | Y42: 0 | Z42: 0 | AA42: 0 | AB42: 0 | AC42: 0 | AD42: 0
B43: 39 | C43: =CONCATENATE("N°-","00",B43,"-2024") -> N°-0039-2024 | D43: 778550234 | E43: Koto | F43: Amadou korka CC | G43: Diabbhéhi | H43: Dakar | I43: 77 855 02 34 | J43: 2000 | K43: 1000 | L43: 0 | M43: =IF(L43>=0,"A JOUR",($L43*($M$12))) -> A JOUR | O43: =IF(L43>=0,"A JOUR",($L43*($M$12+J43))) -> A JOUR | P43: x | Q43: x | T43: A JOUR | Y43: 0 | Z43: 0 | AA43: 0 | AB43: 0 | AC43: 0 | AD43: 0
B44: 40 | C44: =CONCATENATE("N°-","00",B44,"-2024") -> N°-0040-2024 | D44: 778151869 | E44: Koto | F44: Amadou korka | G44: Biilaa | H44: Dakar | I44: 77 815 18 69 | J44: 1000 | K44: 1000 | L44: 0 | M44: =IF(L44>=0,"A JOUR",($L44*($M$12))) -> A JOUR | O44: =IF(L44>=0,"A JOUR",($L44*($M$12+J44))) -> A JOUR | P44: x | Q44: x | T44: A JOUR | Y44: 0 | Z44: 0 | AA44: 0 | AB44: 0 | AC44: 0 | AD44: 0
B45: 44 | C45: =CONCATENATE("N°-","00",B45,"-2024") -> N°-0044-2024 | D45: 778637835 | E45: Mr | F45: Amadou tanou | G45: Dieydiyabhe | H45: Dakar | I45: 77 863 78 35 | J45: 1000 | K45: 1000 | L45: 0 | M45: =IF(L45>=0,"A JOUR",($L45*($M$12))) -> A JOUR | O45: =IF(L45>=0,"A JOUR",($L45*($M$12+J45))) -> A JOUR | P45: x | Q45: x | R45: NT | T45: #N/A | U45: #N/A | V45: NT | Y45: 0 | Z45: 0 | AA45: 0 | AB45: 0 | AC45: 0 | AD45: 0
B46: 45 | C46: =CONCATENATE("N°-","00",B46,"-2024") -> N°-0045-2024 | D46: 773499877 | E46: Mody | F46: Amadou TC | G46: Mamasamba | H46: Dakar | I46: 77 349 98 77 | J46: 2000 | K46: 1000 | L46: 0 | M46: =IF(L46>=0,"A JOUR",($L46*($M$12))) -> A JOUR | O46: =IF(L46>=0,"A JOUR",($L46*($M$12+J46))) -> A JOUR | P46: x | Q46: x | T46: #N/A | U46: GUINEE | Y46: 0 | Z46: 0 | AA46: 0 | AB46: 0 | AC46: 0 | AD46: 0
B47: 46 | C47: =CONCATENATE("N°-","00",B47,"-2024") -> N°-0046-2024 | D47: xxxxxxxx | E47: Mr | F47: Amadou Woury | G47: Ka missidé | H47: Côte d'ivoire | I47: xxxxxxxx | J47: 2000 | K47: 1000 | L47: 0 | M47: =IF(L47>=0,"A JOUR",($L47*($M$12))) -> A JOUR | O47: =IF(L47>=0,"A JOUR",($L47*($M$12+J47))) -> A JOUR | Q47: x | T47: #N/A | U47: #N/A | V47: #N/A | W47: #N/A | X47: #N/A | Y47: 0 | Z47: 0 | AA47: 0 | AB47: 0 | AC47: 0 | AD47: 0
B48: 49 | C48: =CONCATENATE("N°-","00",B48,"-2024") -> N°-0049-2024 | D48: 778018331 | E48: Mr | F48: Boubacar (mariste ) | G48: Kourawoye | H48: Dakar | I48: 77 801 83 31 | J48: 2000 | K48: 1000 | L48: 0 | M48: =IF(L48>=0,"A JOUR",($L48*($M$12))) -> A JOUR | O48: =IF(L48>=0,"A JOUR",($L48*($M$12+J48))) -> A JOUR | P48: x | Q48: x | T48: #N/A | U48: #N/A | V48: #N/A | W48: #N/A | X48: #N/A | Y48: 0 | Z48: 0 | AA48: 0 | AB48: 0 | AC48: 0 | AD48: 0
...

Sheet Feuil1
B4: N° | C4: Code | D4: Titre | E4: Désignation | F4: Missidé | G4: Pays/région | H4: Téléphone | I4: Montant mensuel MSD | J4: Montant mensuel UJDS | K4: Nbre de mois retard | L4: Amande | M4: Avance | N4: Montant dû au 15 01 25 | O4: UJDS | P4: MOUSSIDAL | Q4: STATUT
B5: 1 | C5: N°-0001-2024 | D5: =+VLOOKUP($C5,'Données MSDL'!$C$13:$O$148,3,FALSE) -> Mr | E5: =+VLOOKUP($C5,'Données MSDL'!$C$13:$O$148,4,FALSE) -> Abdoul aziz ibn Elhadji Ibrahima | F5: =+VLOOKUP($C5,'Données MSDL'!$C$13:$O$148,5,FALSE) -> Pétel | G5: =+VLOOKUP($C5,'Données MSDL'!$C$13:$O$148,6,FALSE) -> Dakar | H5: =+VLOOKUP($C5,'Données MSDL'!$C$13:$O$148,7,FALSE) -> 77 877 98 67 | I5: =+VLOOKUP($C5,'Données MSDL'!$C$13:$O$148,8,FALSE) -> 1000 | J5: =+VLOOKUP($C5,'Données MSDL'!$C$13:$O$148,9,FALSE) -> N/A | K5: =+VLOOKUP($C5,'Données MSDL'!$C$13:$O$148,10,FALSE) -> -56 | L5: =+VLOOKUP($C5,'Données MSDL'!$C$13:$O$148,11,FALSE) -> -112000 | M5: =+VLOOKUP($C5,'Données MSDL'!$C$13:$O$148,12,FALSE) -> 0 | N5: =+VLOOKUP($C5,'Données MSDL'!$C$13:$O$148,13,FALSE) -> -168000
B6: 2 | C6: N°-0002-2024 | D6: =+VLOOKUP($C6,'Données MSDL'!$C$13:$O$148,3,FALSE) -> Koto | E6: =+VLOOKUP($C6,'Données MSDL'!$C$13:$O$148,4,FALSE) -> Abdoul ghadry | F6: =+VLOOKUP($C6,'Données MSDL'!$C$13:$O$148,5,FALSE) -> Leysaré | G6: =+VLOOKUP($C6,'Données MSDL'!$C$13:$O$148,6,FALSE) -> Dakar | H6: =+VLOOKUP($C6,'Données MSDL'!$C$13:$O$148,7,FALSE) -> 77 217 52 92 | I6: =+VLOOKUP($C6,'Données MSDL'!$C$13:$O$148,8,FALSE) -> 2000 | J6: =+VLOOKUP($C6,'Données MSDL'!$C$13:$O$148,9,FALSE) -> 1000 | K6: =+VLOOKUP($C6,'Données MSDL'!$C$13:$O$148,10,FALSE) -> 0 | L6: =+VLOOKUP($C6,'Données MSDL'!$C$13:$O$148,11,FALSE) -> A JOUR | M6: =+VLOOKUP($C6,'Données MSDL'!$C$13:$O$148,12,FALSE) -> 0 | N6: =+VLOOKUP($C6,'Données MSDL'!$C$13:$O$148,13,FALSE) -> A JOUR
B7: 3 | C7: N°-0003-2024 | D7: =+VLOOKUP($C7,'Données MSDL'!$C$13:$O$148,3,FALSE) -> Mr | E7: =+VLOOKUP($C7,'Données MSDL'!$C$13:$O$148,4,FALSE) -> Abdoul goudoussy | F7: =+VLOOKUP($C7,'Données MSDL'!$C$13:$O$148,5,FALSE) -> Kourawoye | G7: =+VLOOKUP($C7,'Données MSDL'!$C$13:$O$148,6,FALSE) -> Guinée | H7: =+VLOOKUP($C7,'Données MSDL'!$C$13:$O$148,7,FALSE) -> xxxxxxxx | I7: =+VLOOKUP($C7,'Données MSDL'!$C$13:$O$148,8,FALSE) -> 0 | J7: =+VLOOKUP($C7,'Données MSDL'!$C$13:$O$148,9,FALSE) -> 1000 | K7: =+VLOOKUP($C7,'Données MSDL'!$C$13:$O$148,10,FALSE) -> VG | L7: =+VLOOKUP($C7,'Données MSDL'!$C$13:$O$148,11,FALSE) -> A JOUR | M7: =+VLOOKUP($C7,'Données MSDL'!$C$13:$O$148,12,FALSE) -> 0 | N7: =+VLOOKUP($C7,'Données MSDL'!$C$13:$O$148,13,FALSE) -> A JOUR
B8: 4 | C8: N°-0004-2024 | D8: =+VLOOKUP($C8,'Données MSDL'!$C$13:$O$148,3,FALSE) -> Kaou | E8: =+VLOOKUP($C8,'Données MSDL'!$C$13:$O$148,4,FALSE) -> Abdoul malipan | F8: =+VLOOKUP($C8,'Données MSDL'!$C$13:$O$148,5,FALSE) -> Dowsaré | G8: =+VLOOKUP($C8,'Données MSDL'!$C$13:$O$148,6,FALSE) -> Dakar | H8: =+VLOOKUP($C8,'Données MSDL'!$C$13:$O$148,7,FALSE) -> 77 352 83 33 | I8: =+VLOOKUP($C8,'Données MSDL'!$C$13:$O$148,8,FALSE) -> 2000 | J8: =+VLOOKUP($C8,'Données MSDL'!$C$13:$O$148,9,FALSE) -> N/A | K8: =+VLOOKUP($C8,'Données MSDL'!$C$13:$O$148,10,FALSE) -> -25 | L8: =+VLOOKUP($C8,'Données MSDL'!$C$13:$O$148,11,FALSE) -> -50000 | M8: =+VLOOKUP($C8,'Données MSDL'!$C$13:$O$148,12,FALSE) -> 0 | N8: =+VLOOKUP($C8,'Données MSDL'!$C$13:$O$148,13,FALSE) -> -100000
B9: 5 | C9: N°-0005-2024 | D9: =+VLOOKUP($C9,'Données MSDL'!$C$13:$O$148,3,FALSE) -> Koto | E9: =+VLOOKUP($C9,'Données MSDL'!$C$13:$O$148,4,FALSE) -> Abdoul salam | F9: =+VLOOKUP($C9,'Données MSDL'!$C$13:$O$148,5,FALSE) -> Gobihi | G9: =+VLOOKUP($C9,'Données MSDL'!$C$13:$O$148,6,FALSE) -> Gambie | H9: =+VLOOKUP($C9,'Données MSDL'!$C$13:$O$148,7,FALSE) -> xxxxxxxx | I9: =+VLOOKUP($C9,'Données MSDL'!$C$13:$O$148,8,FALSE) -> 2000 | J9: =+VLOOKUP($C9,'Données MSDL'!$C$13:$O$148,9,FALSE) -> 1000 | K9: =+VLOOKUP($C9,'Données MSDL'!$C$13:$O$148,10,FALSE) -> 0 | L9: =+VLOOKUP($C9,'Données MSDL'!$C$13:$O$148,11,FALSE) -> A JOUR | M9: =+VLOOKUP($C9,'Données MSDL'!$C$13:$O$148,12,FALSE) -> 0 | N9: =+VLOOKUP($C9,'Données MSDL'!$C$13:$O$148,13,FALSE) -> A JOUR
B10: 6 | C10: N°-0006-2024 | D10: =+VLOOKUP($C10,'Données MSDL'!$C$13:$O$148,3,FALSE) -> Mr | E10: =+VLOOKUP($C10,'Données MSDL'!$C$13:$O$148,4,FALSE) -> Abdoul salam petit ibn bappa bala | F10: =+VLOOKUP($C10,'Données MSDL'!$C$13:$O$148,5,FALSE) -> Pétel | G10: =+VLOOKUP($C10,'Données MSDL'!$C$13:$O$148,6,FALSE) -> Dakar | H10: =+VLOOKUP($C10,'Données MSDL'!$C$13:$O$148,7,FALSE) -> 77 478 90 94 | I10: =+VLOOKUP($C10,'Données MSDL'!$C$13:$O$148,8,FALSE) -> 2000 | J10: =+VLOOKUP($C10,'Données MSDL'!$C$13:$O$148,9,FALSE) -> 1000 | K10: =+VLOOKUP($C10,'Données MSDL'!$C$13:$O$148,10,FALSE) -> 0 | L10: =+VLOOKUP($C10,'Données MSDL'!$C$13:$O$148,11,FALSE) -> A JOUR | M10: =+VLOOKUP($C10,'Données MSDL'!$C$13:$O$148,12,FALSE) -> 0 | N10: =+VLOOKUP($C10,'Données MSDL'!$C$13:$O$148,13,FALSE) -> A JOUR
B11: 7 | C11: N°-0007-2024 | D11: =+VLOOKUP($C11,'Données MSDL'!$C$13:$O$148,3,FALSE) -> Koto | E11: =+VLOOKUP($C11,'Données MSDL'!$C$13:$O$148,4,FALSE) -> Abdoul salam ibn Elhadji M. Woury VP | F11: =+VLOOKUP($C11,'Données MSDL'!$C$13:$O$148,5,FALSE) -> Pétel | G11: =+VLOOKUP($C11,'Données MSDL'!$C$13:$O$148,6,FALSE) -> Dakar | H11: =+VLOOKUP($C11,'Données MSDL'!$C$13:$O$148,7,FALSE) -> 78 105 03 63 | I11: =+VLOOKUP($C11,'Données MSDL'!$C$13:$O$148,8,FALSE) -> 2000 | J11: =+VLOOKUP($C11,'Données MSDL'!$C$13:$O$148,9,FALSE) -> 1000 | K11: =+VLOOKUP($C11,'Données MSDL'!$C$13:$O$148,10,FALSE) -> 0 | L11: =+VLOOKUP($C11,'Données MSDL'!$C$13:$O$148,11,FALSE) -> A JOUR | M11: =+VLOOKUP($C11,'Données MSDL'!$C$13:$O$148,12,FALSE) -> 0 | N11: =+VLOOKUP($C11,'Données MSDL'!$C$13:$O$148,13,FALSE) -> A JOUR
B12: 8 | C12: N°-0008-2024 | D12: =+VLOOKUP($C12,'Données MSDL'!$C$13:$O$148,3,FALSE) -> Mr | E12: =+VLOOKUP($C12,'Données MSDL'!$C$13:$O$148,4,FALSE) -> Abdoul salam ibn karamoko Daouda | F12: =+VLOOKUP($C12,'Données MSDL'!$C$13:$O$148,5,FALSE) -> Pétel | G12: =+VLOOKUP($C12,'Données MSDL'!$C$13:$O$148,6,FALSE) -> Gabon | H12: =+VLOOKUP($C12,'Données MSDL'!$C$13:$O$148,7,FALSE) -> +241 04 50 65 55 | I12: =+VLOOKUP($C12,'Données MSDL'!$C$13:$O$148,8,FALSE) -> 5000 | J12: =+VLOOKUP($C12,'Données MSDL'!$C$13:$O$148,9,FALSE) -> N/A | K12: =+VLOOKUP($C12,'Données MSDL'!$C$13:$O$148,10,FALSE) -> 0 | L12: =+VLOOKUP($C12,'Données MSDL'!$C$13:$O$148,11,FALSE) -> A JOUR | M12: =+VLOOKUP($C12,'Données MSDL'!$C$13:$O$148,12,FALSE) -> 0 | N12: =+VLOOKUP($C12,'Données MSDL'!$C$13:$O$148,13,FALSE) -> A JOUR
B13: 9 | C13: N°-0009-2024 | D13: =+VLOOKUP($C13,'Données MSDL'!$C$13:$O$148,3,FALSE) -> Mr | E13: =+VLOOKUP($C13,'Données MSDL'!$C$13:$O$148,4,FALSE) -> Abdoul salam petit | F13: =+VLOOKUP($C13,'Données MSDL'!$C$13:$O$148,5,FALSE) -> Pétel | G13: =+VLOOKUP($C13,'Données MSDL'!$C$13:$O$148,6,FALSE) -> Dakar | H13: =+VLOOKUP($C13,'Données MSDL'!$C$13:$O$148,7,FALSE) -> 77 478 90 94 | I13: =+VLOOKUP($C13,'Données MSDL'!$C$13:$O$148,8,FALSE) -> 2000 | J13: =+VLOOKUP($C13,'Données MSDL'!$C$13:$O$148,9,FALSE) -> 1000 | K13: =+VLOOKUP($C13,'Données MSDL'!$C$13:$O$148,10,FALSE) -> 0 | L13: =+VLOOKUP($C13,'Données MSDL'!$C$13:$O$148,11,FALSE) -> A JOUR | M13: =+VLOOKUP($C13,'Données MSDL'!$C$13:$O$148,12,FALSE) -> 0 | N13: =+VLOOKUP($C13,'Données MSDL'!$C$13:$O$148,13,FALSE) -> A JOUR
B14: 10 | C14: N°-0010-2024 | D14: =+VLOOKUP($C14,'Données MSDL'!$C$13:$O$148,3,FALSE) -> Mr | E14: =+VLOOKUP($C14,'Données MSDL'!$C$13:$O$148,4,FALSE) -> Abdoul salam PP | F14: =+VLOOKUP($C14,'Données MSDL'!$C$13:$O$148,5,FALSE) -> Dieydiyabhe | G14: =+VLOOKUP($C14,'Données MSDL'!$C$13:$O$148,6,FALSE) -> Dakar | H14: =+VLOOKUP($C14,'Données MSDL'!$C$13:$O$148,7,FALSE) -> 77 679 26 24 | I14: =+VLOOKUP($C14,'Données MSDL'!$C$13:$O$148,8,FALSE) -> 1000 | J14: =+VLOOKUP($C14,'Données MSDL'!$C$13:$O$148,9,FALSE) -> 1000 | K14: =+VLOOKUP($C14,'Données MSDL'!$C$13:$O$148,10,FALSE) -> 0 | L14: =+VLOOKUP($C14,'Données MSDL'!$C$13:$O$148,11,FALSE) -> A JOUR | M14: =+VLOOKUP($C14,'Données MSDL'!$C$13:$O$148,12,FALSE) -> 0 | N14: =+VLOOKUP($C14,'Données MSDL'!$C$13:$O$148,13,FALSE) -> A JOUR
B15: 11 | C15: N°-0011-2024 | D15: =+VLOOKUP($C15,'Données MSDL'!$C$13:$O$148,3,FALSE) -> Mr | E15: =+VLOOKUP($C15,'Données MSDL'!$C$13:$O$148,4,FALSE) -> Abdoul salam PP (ivoire) | F15: =+VLOOKUP($C15,'Données MSDL'!$C$13:$O$148,5,FALSE) -> Dowsaré | G15: =+VLOOKUP($C15,'Données MSDL'!$C$13:$O$148,6,FALSE) -> Dakar | H15: =+VLOOKUP($C15,'Données MSDL'!$C$13:$O$148,7,FALSE) -> 77 577 99 80 | I15: =+VLOOKUP($C15,'Données MSDL'!$C$13:$O$148,8,FALSE) -> 1000 | J15: =+VLOOKUP($C15,'Données MSDL'!$C$13:$O$148,9,FALSE) -> 1000 | K15: =+VLOOKUP($C15,'Données MSDL'!$C$13:$O$148,10,FALSE) -> -2 | L15: =+VLOOKUP($C15,'Données MSDL'!$C$13:$O$148,11,FALSE) -> -4000 | M15: =+VLOOKUP($C15,'Données MSDL'!$C$13:$O$148,12,FALSE) -> 0 | N15: =+VLOOKUP($C15,'Données MSDL'!$C$13:$O$148,13,FALSE) -> -6000
B16: 12 | C16: N°-0012-2024 | D16: =+VLOOKUP($C16,'Données MSDL'!$C$13:$O$148,3,FALSE) -> Mr | E16: =+VLOOKUP($C16,'Données MSDL'!$C$13:$O$148,4,FALSE) -> Abdoulaye | F16: =+VLOOKUP($C16,'Données MSDL'!$C$13:$O$148,5,FALSE) -> Daandé Mboully | G16: =+VLOOKUP($C16,'Données MSDL'!$C$13:$O$148,6,FALSE) -> Guinée | H16: =+VLOOKUP($C16,'Données MSDL'!$C$13:$O$148,7,FALSE) -> 0 | I16: =+VLOOKUP($C16,'Données MSDL'!$C$13:$O$148,8,FALSE) -> 0 | J16: =+VLOOKUP($C16,'Données MSDL'!$C$13:$O$148,9,FALSE) -> 1000 | K16: =+VLOOKUP($C16,'Données MSDL'!$C$13:$O$148,10,FALSE) -> VG | L16: =+VLOOKUP($C16,'Données MSDL'!$C$13:$O$148,11,FALSE) -> A JOUR | M16: =+VLOOKUP($C16,'Données MSDL'!$C$13:$O$148,12,FALSE) -> 0 | N16: =+VLOOKUP($C16,'Données MSDL'!$C$13:$O$148,13,FALSE) -> A JOUR
... B137: 133 | C137: N°-0133-2024 | D137: =+VLOOKUP($C137,'Données MSDL'!$C$13:$O$148,3,FALSE) -> Koto | E137: =+VLOOKUP($C137,'Données MSDL'!$C$13:$O$148,4,FALSE) -> Woury | F137: =+VLOOKUP($C137,'Données MSDL'!$C$13:$O$148,5,FALSE) -> Dowsaré | G137: =+VLOOKUP($C137,'Données MSDL'!$C$13:$O$148,6,FALSE) -> Guinée | H137: =+VLOOKUP($C137,'Données MSDL'!$C$13:$O$148,7,FALSE) -> xxxxxxxx | I137: =+VLOOKUP($C137,'Données MSDL'!$C$13:$O$148,8,FALSE) -> N/A | J137: =+VLOOKUP($C137,'Données MSDL'!$C$13:$O$148,9,FALSE) -> N/A | K137: =+VLOOKUP($C137,'Données MSDL'!$C$13:$O$148,10,FALSE) -> 0 | L137: =+VLOOKUP($C137,'Données MSDL'!$C$13:$O$148,11,FALSE) -> A JOUR | M137: =+VLOOKUP($C137,'Données MSDL'!$C$13:$O$148,12,FALSE) -> 0 | N137: =+VLOOKUP($C137,'Données MSDL'!$C$13:$O$148,13,FALSE) -> A JOUR

Sheet Feuil2
B5: SOLDE ANTERIEUR
B6: DEPENSES DU MOIS
B7: VERSEMENT DU MOIS
B8: REVENUS SUPPLEMENTAIRE DU MOIS
B9: TOTAL SOLDE ACTUEL
B11: SOLDE ANTERIEUR
B12: DEPENSES DU MOIS
B13: VERSEMENT DU MOIS
B14: REVENUS SUPPLEMENTAIRE DU MOIS
B15: TOTAL SOLDE ACTUEL

Sheet Données MSDL (2)
B6: UNION DES JEUNES DE DOUKA SELEYABE
G8: =+TODAY() -> 46001
B10: LISTE OFFICIELLE DES MEMBRES
M12: 2000 | O12: =SUM(O14:O148) -> 280500 | U12: A JOUR | V12: GUINEE | W12: NT | X12: DETTE
B13: N° | C13: Code | D13: Téléphone | E13: Titre | F13: Désignation | G13: Missidé | H13: Pays/région | I13: Téléphone | J13: Montant mensuel MSD | K13: Montant mensuel UJDS | L13: Nbre de mois retard | M13: Amande | N13: Versement | O13: Avance | P13: Montant dû au 28 02 25 | Q13: UJDS | R13: MOUSSIDAL | S13: STATUT | Z13: 45689 | AA13: 45717 | AB13: 45748 | AC13: 45778 | AD13: 45809 | AE13: 45839 | AF13: 45870 | AG13: 45901 | AH13: 45931 | AI13: 45962 | AJ13: 45992 | AK13: 46023 | AL13: 46054 | AM13: 46082 | AN13: 46113 | AO13: 46143 | AP13: 46174 | AQ13: 45962 | AR13: 45992
B14: 1 | C14: =CONCATENATE("N°-","000",B14,"-2024") -> N°-0001-2024 | D14: 778779867 | E14: Mr | F14: Abdoul aziz ibn Elhadji Ibrahima | G14: Pétel | H14: Dakar | I14: 77 877 98 67 | J14: 1000 | K14: N/A | L14: =+IF(SUM($Z14:$AR14)>0,0,SUM($Z14:$AR14)) -> -57 | M14: =IF(L14>=0,"A JOUR",($L14*($M$12))) -> -114000 | N14: =IF(L14>0,SUM($Z14:$AR14)*$J14,0) -> 0 | O14: =+IF(L14>0,L14*J14,0) -> 0 | P14: =IF(L14>=0,"A JOUR",($L14*($M$12+J14)+O14)) -> -171000 | R14: x | U14: #N/A | V14: #N/A | W14: #N/A | X14: 1000 | Y14: 56 | Z14: -57
B15: 2 | C15: =CONCATENATE("N°-","000",B15,"-2024") -> N°-0002-2024 | D15: 772175292 | E15: Koto | F15: Abdoul ghadry | G15: Leysaré | H15: Dakar | I15: 77 217 52 92 | J15: 2000 | K15: 1000 | L15: 0 | M15: =IF(L15>=0,"A JOUR",($L15*($M$12))) -> A JOUR | N15: =IF(L15>0,SUM($Z15:$AR15)*$J15,0) -> 0 | O15: =+IF(L15>0,L15*J15,0) -> 0 | P15: =IF(L15>=0,"A JOUR",($L15*($M$12+J15)+O15)) -> A JOUR | Q15: x | R15: x | U15: A JOUR | Z15: 1
B16: 3 | C16: =CONCATENATE("N°-","000",B16,"-2024") -> N°-0003-2024 | D16: xxxxxxxx | E16: Mr | F16: Abdoul goudoussy | G16: Kourawoye | H16: Guinée | I16: xxxxxxxx | K16: 1000 | L16: VG | M16: =IF(L16>=0,"A JOUR",($L16*($M$12))) -> A JOUR | N16: =IF(L16>0,SUM($Z16:$AR16)*$J16,0) -> 0 | P16: =IF(L16>=0,"A JOUR",($L16*($M$12+J16)+O16)) -> A JOUR | Q16: x | S16: VG | U16: #N/A | V16: #N/A | W16: #N/A | X16: #N/A | Y16: #N/A | Z16: VG
B17: 4 | C17: =CONCATENATE("N°-","000",B17,"-2024") -> N°-0004-2024 | D17: 773528333 | E17: Kaou | F17: Abdoul malipan | G17: Dowsaré | H17: Dakar | I17: 77 352 83 33 | J17: 2000 | K17: N/A | L17: =+SUM($Z17:$AR17) -> -27 | M17: =IF(L17>=0,"A JOUR",($L17*($M$12))) -> -54000 | N17: =IF(L17>0,SUM($Z17:$AR17)*$J17,0) -> 0 | O17: =+IF(L17>0,L17*J17,0) -> 0 | P17: =IF(L17>=0,"A JOUR",($L17*($M$12+J17)+O17)) -> -108000 | R17: x | U17: #N/A | V17: #N/A | W17: #N/A | X17: 2000 | Y17: 25 | Z17: -27
B18: 5 | C18: =CONCATENATE("N°-","000",B18,"-2024") -> N°-0005-2024 | D18: xxxxxxxx | E18: Koto | F18: Abdoul salam | G18: Gobihi | H18: Gambie | I18: xxxxxxxx | J18: 2000 | K18: 1000 | M18: =IF(L18>=0,"A JOUR",($L18*($M$12))) -> A JOUR | N18: =IF(L18>0,SUM($Z18:$AR18)*$J18,0) -> 0 | O18: =+IF(L18>0,L18*J18,0) -> 0 | P18: =IF(L18>=0,"A JOUR",($L18*($M$12+J18)+O18)) -> A JOUR | R18: x | U18: #N/A | V18: #N/A | W18: #N/A | X18: #N/A | Y18: #N/A
B19: 6 | C19: =CONCATENATE("N°-","000",B19,"-2024") -> N°-0006-2024 | D19: 774789094 | E19: Mr | F19: Abdoul salam petit ibn bappa bala | G19: Pétel | H19: Dakar | I19: 77 478 90 94 | J19: 2000 | K19: 1000 | L19: 0 | M19: =IF(L19>=0,"A JOUR",($L19*($M$12))) -> A JOUR | N19: =IF(L19>0,SUM($Z19:$AR19)*$J19,0) -> 0 | O19: =+IF(L19>0,L19*J19,0) -> 0 | P19: =IF(L19>=0,"A JOUR",($L19*($M$12+J19)+O19)) -> A JOUR | Q19: x | R19: x | U19: A JOUR
B20: 7 | C20: =CONCATENATE("N°-","000",B20,"-2024") -> N°-0007-2024 | D20: 781050363 | E20: Koto | F20: Abdoul salam ibn Elhadji M. Woury VP | G20: Pétel | H20: Dakar | I20: 78 105 03 63 | J20: 2000 | K20: 1000 | L20: 0 | M20: =IF(L20>=0,"A JOUR",($L20*($M$12))) -> A JOUR | N20: =IF(L20>0,SUM($Z20:$AR20)*$J20,0) -> 0 | O20: =+IF(L20>0,L20*J20,0) -> 0 | P20: =IF(L20>=0,"A JOUR",($L20*($M$12+J20)+O20)) -> A JOUR | Q20: x | R20: x | U20: A JOUR | Z20: 1
B21: 8 | C21: =CONCATENATE("N°-","000",B21,"-2024") -> N°-0008-2024 | D21: +24104506555 | E21: Mr | F21: Abdoul salam ibn karamoko Daouda | G21: Pétel | H21: Gabon | I21: +241 04 50 65 55 | J21: 5000 | K21: N/A | M21: =IF(L21>=0,"A JOUR",($L21*($M$12))) -> A JOUR | N21: =IF(L21>0,SUM($Z21:$AR21)*$J21,0) -> 0 | P21: =IF(L21>=0,"A JOUR",($L21*($M$12+J21)+O21)) -> A JOUR | R21: x | U21: #N/A | V21: #N/A | W21: #N/A | X21: #N/A | Y21: #N/A
B22: 9 | C22: =CONCATENATE("N°-","000",B22,"-2024") -> N°-0009-2024 | D22: 774789094 | E22: Mr | F22: Abdoul salam petit | G22: Pétel | H22: Dakar | I22: 77 478 90 94 | J22: 2000 | K22: 1000 | L22: 0 | M22: =IF(L22>=0,"A JOUR",($L22*($M$12))) -> A JOUR | N22: =IF(L22>0,SUM($Z22:$AR22)*$J22,0) -> 0 | O22: =+IF(L22>0,L22*J22,0) -> 0 | P22: =IF(L22>=0,"A JOUR",($L22*($M$12+J22)+O22)) -> A JOUR | Q22: x | R22: x | U22: A JOUR | Z22: NT
B23: 10 | C23: =CONCATENATE("N°-","00",B23,"-2024") -> N°-0010-2024 | D23: 776792624 | E23: Mr | F23: Abdoul salam PP | G23: Dieydiyabhe | H23: Dakar | I23: 77 679 26 24 | J23: 1000 | K23: 1000 | L23: 0 | M23: =IF(L23>=0,"A JOUR",($L23*($M$12))) -> A JOUR | N23: =IF(L23>0,SUM($Z23:$AR23)*$J23,0) -> 0 | O23: =+IF(L23>0,L23*J23,0) -> 0 | P23: =IF(L23>=0,"A JOUR",($L23*($M$12+J23)+O23)) -> A JOUR | Q23: x | R23: x | U23: A JOUR
B24: 11 | C24: =CONCATENATE("N°-","00",B24,"-2024") -> N°-0011-2024 | D24: 775779980 | E24: Mr | F24: Abdoul salam PP (ivoire) | G24: Dowsaré | H24: Dakar | I24: 77 577 99 80 | J24: 1000 | K24: 1000 | L24: =+SUM($Z24:$AR24) -> -4 | M24: =IF(L24>=0,"A JOUR",($L24*($M$12))) -> -8000 | N24: =IF(L24>0,SUM($Z24:$AR24)*$J24,0) -> 0 | P24: =IF(L24>=0,"A JOUR",($L24*($M$12+J24)+O24)) -> -12000 | Q24: x | R24: x | U24: #N/A | V24: #N/A | W24: #N/A | X24: 1000 | Y24: 2 | Z24: -4
B25: 12 | C25: =CONCATENATE("N°-","00",B25,"-2024") -> N°-0012-2024 | E25: Mr | F25: Abdoulaye | G25: Daandé Mboully | H25: Guinée | K25: 1000 | L25: VG | M25: =IF(L25>=0,"A JOUR",($L25*($M$12))) -> A JOUR | N25: =IF(L25>0,SUM($Z25:$AR25)*$J25,0) -> 0 | P25: =IF(L25>=0,"A JOUR",($L25*($M$12+J25)+O25)) -> A JOUR | Q25: x | S25: VG | U25: #N/A | V25: #N/A | W25: #N/A | X25: #N/A | Y25: #N/A | Z25: VG
B26: 13 | C26: =CONCATENATE("N°-","00",B26,"-2024") -> N°-0013-2024 | D26: xxxxxxxx | E26: Mr | F26: Abdoulaye | G26: Kourawoye | H26: Côte d'ivoire | I26: xxxxxxxx | J26: 1000 | K26: N/A | M26: =IF(L26>=0,"A JOUR",($L26*($M$12))) -> A JOUR | N26: =IF(L26>0,SUM($Z26:$AR26)*$J26,0) -> 0 | P26: =IF(L26>=0,"A JOUR",($L26*($M$12+J26)+O26)) -> A JOUR | Q26: x | U26: #N/A | V26: #N/A | W26: #N/A | X26: #N/A | Y26: #N/A
B27: 14 | C27: =CONCATENATE("N°-","00",B27,"-2024") -> N°-0014-2024 | D27: 781413617 | E27: Grand | F27: Abdoulaye (Laye) | G27: Biilaa | H27: Guinée | I27: 78 141 36 17 | J27: 1000 | K27: 1000 | L27: 0 | M27: =IF(L27>=0,"A JOUR",($L27*($M$12))) -> A JOUR | N27: =IF(L27>0,SUM($Z27:$AR27)*$J27,0) -> 0 | O27: =+IF(L27>0,L27*J27,0) -> 0 | P27: =IF(L27>=0,"A JOUR",($L27*($M$12+J27)+O27)) -> A JOUR | Q27: x | R27: x | U27: #N/A | V27: GUINEE | Z27: VG
B28: 15 | C28: =CONCATENATE("N°-","00",B28,"-2024") -> N°-0015-2024 | D28: +24106399421 | E28: Grand | F28: Abdoulaye (Laye) gabonais | G28: Pétel | H28: Dakar | I28: +241 06 39 94 21 | J28: 2000 | K28: N/A | L28: =+SUM($Z28:$AR28) -> -6 | M28: =IF(L28>=0,"A JOUR",($L28*($M$12))) -> -12000 | N28: =IF(L28>0,SUM($Z28:$AR28)*$J28,0) -> 0 | P28: =IF(L28>=0,"A JOUR",($L28*($M$12+J28)+O28)) -> -24000 | R28: x | U28: #N/A | V28: #N/A | W28: #N/A | X28: 2000 | Y28: 4 | Z28: -6
B29: 16 | C29: =CONCATENATE("N°-","00",B29,"-2024") -> N°-0016-2024 | D29: 777255426 | E29: Mr | F29: Abdoulaye djibril KZA ibnou samara | G29: Dowsaré | H29: Casamance | I29: 77 725 54 26 | J29: 1500 | K29: N/A | L29: 11 | M29: =IF(L29>=0,"A JOUR",($L29*($M$12))) -> A JOUR | N29: =IF(L29>0,SUM($Z29:$AR29)*$J29,0) -> 16500 | O29: =+IF(L29>0,L29*J29,0) -> 16500 | P29: =IF(L29>=0,"A JOUR",($L29*($M$12+J29)+O29)) -> A JOUR | Q29: x | R29: x | S29: =+IF(L29>0,L29*J29,0) -> 16500 | U29: A JOUR | Z29: 1 | AA29: 1 | AB29: 1 | AC29: 1 | AD29: 1 | AE29: 1 | AF29: 1 | AG29: 1 | AH29: 1 | AI29: 1 | AJ29: 1
B30: 17 | C30: =CONCATENATE("N°-","00",B30,"-2024") -> N°-0017-2024 | E30: Mr | F30: Abdoulaye ka gallé | G30: Biilaa | H30: Guinée | K30: N/A | L30: VG | M30: =IF(L30>=0,"A JOUR",($L30*($M$12))) -> A JOUR | N30: =IF(L30>0,SUM($Z30:$AR30)*$J30,0) -> 0 | P30: =IF(L30>=0,"A JOUR",($L30*($M$12+J30)+O30)) -> A JOUR | S30: VG | U30: #N/A | V30: #N/A | W30: #N/A | X30: #N/A | Y30: #N/A | Z30: VG
B31: 18 | C31: =CONCATENATE("N°-","00",B31,"-2024") -> N°-0018-2024 | D31: 774042497 | E31: Mr | F31: Abdourahmane TRS | G31: Mamasamba | H31: Dakar | I31: 77 404 24 97 | J31: 5000 | K31: 1000 | L31: 0 | M31: =IF(L31>=0,"A JOUR",($L31*($M$12))) -> A JOUR | N31: =IF(L31>0,SUM($Z31:$AR31)*$J31,0) -> 0 | O31: =+IF(L31>0,L31*J31,0) -> 0 | P31: =IF(L31>=0,"A JOUR",($L31*($M$12+J31)+O31)) -> A JOUR | Q31: x | R31: x | U31: #N/A | V31: #N/A | W31: #N/A | X31: #N/A | Y31: #N/A | Z31: 1 | AA31: 1 | AB31: 1 | AC31: 1 | AD31: 1 | AE31: 1 | AF31: 1 | AG31: 1 | AH31: 1 | AI31: 1 | AJ31: 1
B32: 19 | C32: =CONCATENATE("N°-","00",B32,"-2024") -> N°-0019-2024 | D32: 774473167 | E32: Koto | F32: Ablaye TSA | G32: Bolorrou | H32: Dakar | I32: 77 447 31 67 | J32: 1500 | K32: 1000 | L32: 0 | M32: =IF(L32>=0,"A JOUR",($L32*($M$12))) -> A JOUR | N32: =IF(L32>0,SUM($Z32:$AR32)*$J32,0) -> 0 | O32: =+IF(L32>0,L32*J32,0) -> 0 | P32: =IF(L32>=0,"A JOUR",($L32*($M$12+J32)+O32)) -> A JOUR | Q32: x | R32: x | U32: A JOUR | Z32: 1
B33: 20 | C33: =CONCATENATE("N°-","00",B33,"-2024") -> N°-0020-2024 | D33: 777119328 | E33: Kaou | F33: Ahmadou Korka ibn bappa bala | G33: Pétel | H33: Dakar | I33: 777119328 | J33: 1000 | K33: 1000 | L33: =+SUM($Z33:$AR33) -> -6 | M33: =IF(L33>=0,"A JOUR",($L33*($M$12))) -> -12000 | N33: =IF(L33>0,SUM($Z33:$AR33)*$J33,0) -> 0 | O33: =+IF(L33>0,L33*J33,0) -> 0 | P33: =IF(L33>=0,"A JOUR",($L33*($M$12+J33)+O33)) -> -18000 | U33: #N/A | V33: #N/A | W33: #N/A | X33: 1000 | Y33: 3 | Z33: -6
B34: 21 | C34: =CONCATENATE("N°-","00",B34,"-2024") -> N°-0021-2024 | D34: 783520425 | E34: Mr | F34: Alassana ibn Elhadji M. Woury | G34: Pétel | H34: Dakar | I34: 78 352 04 25 | J34: 1000 | K34: 1000 | L34: 0 | M34: =IF(L34>=0,"A JOUR",($L34*($M$12))) -> A JOUR | N34: =IF(L34>0,SUM($Z34:$AR34)*$J34,0) -> 0 | O34: =+IF(L34>0,L34*J34,0) -> 0 | P34: =IF(L34>=0,"A JOUR",($L34*($M$12+J34)+O34)) -> A JOUR | R34: x | S34: NT | U34: #N/A | V34: #N/A | W34: NT | Z34: NT
B35: 22 | C35: =CONCATENATE("N°-","00",B35,"-2024") -> N°-0022-2024 | D35: 767652193 | E35: Mr | F35: Alassana Macoss | G35: Dowsaré | H35: Dakar | I35: 76 765 21 93 | J35: 1000 | K35: 1000 | L35: 0 | M35: =IF(L35>=0,"A JOUR",($L35*($M$12))) -> A JOUR | N35: =IF(L35>0,SUM($Z35:$AR35)*$J35,0) -> 0 | O35: =+IF(L35>0,L35*J35,0) -> 0 | P35: =IF(L35>=0,"A JOUR",($L35*($M$12+J35)+O35)) -> A JOUR | Q35: x | R35: x | S35: NT | U35: #N/A | V35: #N/A | W35: NT | Z35: NT
B36: 23 | C36: =CONCATENATE("N°-","00",B36,"-2024") -> N°-0023-2024 | D36: 783520425 | E36: Mr | F36: Alousseynou ibn Elhadji M. Woury | G36: Pétel | H36: Dakar | I36: 78 352 04 25 | J36: 1000 | K36: 1000 | L36: 0 | M36: =IF(L36>=0,"A JOUR",($L36*($M$12))) -> A JOUR | N36: =IF(L36>0,SUM($Z36:$AR36)*$J36,0) -> 0 | O36: =+IF(L36>0,L36*J36,0) -> 0 | P36: =IF(L36>=0,"A JOUR",($L36*($M$12+J36)+O36)) -> A JOUR | R36: x | S36: NT | U36: #N/A | V36: #N/A | W36: NT | Z36: NT
B37: 24 | C37: =CONCATENATE("N°-","00",B37,"-2024") -> N°-0024-2024 | E37: Mr | F37: Alousseynou Pecosse | G37: Dowsaré | H37: Guinée | K37: N/A | L37: VG | M37: =IF(L37>=0,"A JOUR",($L37*($M$12))) -> A JOUR | N37: =IF(L37>0,SUM($Z37:$AR37)*$J37,0) -> 0 | P37: =IF(L37>=0,"A JOUR",($L37*($M$12+J37)+O37)) -> A JOUR | Q37: x | S37: VG | U37: #N/A | V37: #N/A | W37: #N/A | X37: #N/A | Y37: #N/A | Z37: VG
B38: 25 | C38: =CONCATENATE("N°-","00",B38,"-2024") -> N°-0025-2024 | E38: Mr | F38: Alpha (France) | G38: Dieydiyabhe | H38: France | K38: 1000 | M38: =IF(L38>=0,"A JOUR",($L38*($M$12))) -> A JOUR | N38: =IF(L38>0,SUM($Z38:$AR38)*$J38,0) -> 0 | O38: =+IF(L38>0,L38*J38,0) -> 0 | P38: =IF(L38>=0,"A JOUR",($L38*($M$12+J38)+O38)) -> A JOUR | U38: #N/A | V38: #N/A | W38: #N/A | X38: #N/A | Y38: #N/A
B39: 26 | C39: =CONCATENATE("N°-","00",B39,"-2024") -> N°-0026-2024 | D39: 772289487 | E39: Mr | F39: Alpha amadou ibn bappa bala | G39: Pétel | H39: Dakar | I39: 77 228 94 87 | J39: 1000 | K39: 1000 | L39: 0 | M39: =IF(L39>=0,"A JOUR",($L39*($M$12))) -> A JOUR | N39: =IF(L39>0,SUM($Z39:$AR39)*$J39,0) -> 0 | O39: =+IF(L39>0,L39*J39,0) -> 0 | P39: =IF(L39>=0,"A JOUR",($L39*($M$12+J39)+O39)) -> A JOUR | Q39: x | R39: x | U39: A JOUR | Z39: 1 | AA39: 1 | AB39: 1 | AC39: 1 | AD39: 1 | AE39: 1 | AF39: 1 | AG39: 1 | AH39: 1 | AI39: 1 | AJ39: 1
B40: 27 | C40: =CONCATENATE("N°-","00",B40,"-2024") -> N°-0027-2024 | D40: 781261182 | E40: Mr | F40: Alpha Amirou ibn Elhadji Ibrahima | G40: Pétel | H40: Dakar | I40: 78 126 11 82 | J40: 1000 | K40: 1000 | L40: =+SUM($Z40:$AR40) -> -6 | M40: =IF(L40>=0,"A JOUR",($L40*($M$12))) -> -12000 | N40: =IF(L40>0,SUM($Z40:$AR40)*$J40,0) -> 0 | O40: =+IF(L40>0,L40*J40,0) -> 0 | P40: =IF(L40>=0,"A JOUR",($L40*($M$12+J40)+O40)) -> -18000 | R40: x | S40: NT | U40: #N/A | V40: #N/A | W40: #N/A | X40: 1000 | Y40: 6 | Z40: -6
B41: 28 | C41: =CONCATENATE("N°-","00",B41,"-2024") -> N°-0028-2024 | D41: 772202046 | E41: Koto | F41: alpha KZA ibnou samara | G41: Dowsaré | H41: Casamance | I41: 77 220 20 46 | J41: 2000 | K41: 1000 | L41: 11 | M41: =IF(L41>=0,"A JOUR",($L41*($M$12))) -> A JOUR | N41: =IF(L41>0,SUM($Z41:$AR41)*$J41,0) -> 2000 | O41: =+IF(L41>0,L41*J41,0) -> 22000 | P41: =IF(L41>=0,"A JOUR",($L41*($M$12+J41)+O41)) -> A JOUR | Q41: x | R41: x | U41: A JOUR | Z41: 1
B42: 29 | C42: =CONCATENATE("N°-","00",B42,"-2024") -> N°-0029-2024 | D42: 781346347 | E42: Bappa | F42: Alpha oumar | G42: Mamasamba | H42: Dakar | I42: 78 134 63 47 | J42: 2000 | K42: 1000 | L42: =4-4 -> 0 | M42: =IF(L42>=0,"A JOUR",($L42*($M$12))) -> A JOUR | N42: =IF(L42>0,SUM($Z42:$AR42)*$J42,0) -> 0 | O42: =+IF(L42>0,L42*J42,0) -> 0 | P42: =IF(L42>=0,"A JOUR",($L42*($M$12+J42)+O42)) -> A JOUR | Q42: x | R42: x | U42: A JOUR | Z42: 1
B43: 30 | C43: =CONCATENATE("N°-","00",B43,"-2024") -> N°-0030-2024 | D43: xxxxxxxx | E43: Koto | F43: Alpha oumar gabonais | G43: Dowsaré | H43: Togo | I43: xxxxxxxx | J43: 4000 | K43: 1000 | M43: =IF(L43>=0,"A JOUR",($L43*($M$12))) -> A JOUR | N43: =IF(L43>0,SUM($Z43:$AR43)*$J43,0) -> 0 | P43: =IF(L43>=0,"A JOUR",($L43*($M$12+J43)+O43)) -> A JOUR | Q43: x | R43: x | U43: #N/A | V43: #N/A | W43: #N/A | X43: #N/A | Y43: #N/A
B44: 31 | C44: =CONCATENATE("N°-","00",B44,"-2024") -> N°-0031-2024 | D44: +24102253222 | E44: Koto | F44: Alpha oumar ibn karamoko Daouda | G44: Pétel | H44: Gabon | I44: +241 02 25 32 22 | J44: 5000 | K44: N/A | M44: =IF(L44>=0,"A JOUR",($L44*($M$12))) -> A JOUR | N44: =IF(L44>0,SUM($Z44:$AR44)*$J44,0) -> 0 | P44: =IF(L44>=0,"A JOUR",($L44*($M$12+J44)+O44)) -> A JOUR | R44: x | U44: #N/A | V44: #N/A | W44: #N/A | X44: #N/A | Y44: #N/A
B45: 32 | C45: =CONCATENATE("N°-","00",B45,"-2024") -> N°-0032-2024 | D45: 774997775 | E45: Koto | F45: Alpha Oumar togolais | G45: Dowsaré | H45: Dakar | I45: 77 499 77 75 | J45: 2000 | K45: 1000 | L45: 2 | M45: =IF(L45>=0,"A JOUR",($L45*($M$12))) -> A JOUR | N45: =IF(L45>0,SUM($Z45:$AR45)*$J45,0) -> 2000 | O45: =+IF(L45>0,L45*J45,0) -> 4000 | P45: =IF(L45>=0,"A JOUR",($L45*($M$12+J45)+O45)) -> A JOUR | Q45: x | R45: x | U45: A JOUR | Z45: 1
B46: 33 | C46: =CONCATENATE("N°-","00",B46,"-2024") -> N°-0033-2024 | E46: Mr | F46: Alpha Saliou ibn Elhadji M. Woury | G46: Pétel | H46: Guinée | K46: 1000 | L46: VG | M46: =IF(L46>=0,"A JOUR",($L46*($M$12))) -> A JOUR | N46: =IF(L46>0,SUM($Z46:$AR46)*$J46,0) -> 0 | P46: =IF(L46>=0,"A JOUR",($L46*($M$12+J46)+O46)) -> A JOUR | S46: VG | U46: #N/A | V46: #N/A | W46: #N/A | X46: #N/A | Y46: #N/A | Z46: VG
B47: 34 | C47: =CONCATENATE("N°-","00",B47,"-2024") -> N°-0034-2024 | D47: 776709584 | E47: Oustaz | F47: Amadou | G47: Bowell | H47: Guinée | I47: 77 670 95 84 | J47: 2500 | K47: 1000 | L47: 0 | M47: =IF(L47>=0,"A JOUR",($L47*($M$12))) -> A JOUR | N47: =IF(L47>0,SUM($Z47:$AR47)*$J47,0) -> 0 | O47: =+IF(L47>0,L47*J47,0) -> 0 | P47: =IF(L47>=0,"A JOUR",($L47*($M$12+J47)+O47)) -> A JOUR | Q47: x | R47: x | S47: NT | U47: #N/A | V47: GUINEE | Z47: VG
B48: 35 | C48: =CONCATENATE("N°-","00",B48,"-2024") -> N°-0035-2024 | D48: 776623868 | E48: Mr | F48: Amadou bobo (mariste) | G48: Dowsaré | H48: Dakar | I48: 77 662 38 68 | J48: 2000 | K48: 1000 | L48: 0 | M48: =IF(L48>=0,"A JOUR",($L48*($M$12))) -> A JOUR | N48: =IF(L48>0,SUM($Z48:$AR48)*$J48,0) -> 0 | O48: =+IF(L48>0,L48*J48,0) -> 0 | P48: =IF(L48>=0,"A JOUR",($L48*($M$12+J48)+O48)) -> A JOUR | Q48: x | R48: x | U48: A JOUR | Z48: 1 | AA48: 1 | AB48: 1 | AC48: 1 | AD48: 1 | AE48: 1 | AF48: 1 | AG48: 1 | AH48: 1 | AI48: 1 | AJ48: 1
...

Sheet Données MSDL BON
B6: UNION DES JEUNES DE DOUKA SELEYABE
G8: =+TODAY() -> 46001
B10: LISTE OFFICIELLE DES MEMBRES
U11: 9000 DU PAR DAOUDA + 50K + AMENDE
M12: 2000
B13: N° | C13: Code | D13: Téléphone | E13: Titre | F13: Désignation | G13: Missidé | H13: Pays/région | I13: Téléphone | J13: Montant mensuel MSD | K13: Montant mensuel UJDS | L13: Nbre de mois retard | M13: Amande | N13: Avance Ancien | O13: Avance | P13: Amande MSDL | Q13: Montant versé | R13: Montant dû au 31 12 25 | S13: UJDS | T13: MOUSSIDAL | U13: STATUT | V13: 45689 | W13: 45717 | X13: 45748 | Y13: 45778 | Z13: 45809 | AA13: 45839 | AB13: 45870 | AC13: 45901 | AD13: 45931 | AE13: 45962 | AF13: 45992 | AH13: 45717 | AI13: 45748 | AJ13: 45778 | AK13: 45809 | AL13: 45839 | AM13: 45870 | AN13: 45901 | AO13: 45931 | AP13: 45962 | AQ13: 45992
